好的，这是一个非常核心且精妙的设计点，也是 C++ 协程相比传统异步模型（如回调、`std::future`）的一大优势。

我们来详细拆解这个“无需同步的异步执行”机制，并用代码来揭示其背后的并发风险。

### 1\. 问题的根源：传统异步模型的竞态条件

在看协程的解决方案之前，我们先看看老问题是什么。假设我们用一个类似回调的风格来写异步代码：

```cpp
// 伪代码：传统异步模型
void traditional_async_example() {
    // 准备一个状态，用来接收异步操作的结果
    bool operation_complete = false;
    std::mutex mtx;
    std::condition_variable cv;

    // 1. 启动异步操作，并注册回调
    start_async_read([&]{
        // ---- 这是在另一个线程执行的回调 ----
        std::lock_guard lock(mtx);
        operation_complete = true;
        cv.notify_one();
        // ------------------------------------
    });

    // 2. 进入等待状态
    std::unique_lock lock(mtx);
    cv.wait(lock, [&]{ return operation_complete; });
}
```

这里潜藏着一个经典的竞态条件（Race Condition），也被称为“丢失的唤醒” (Lost Wakeup)：

  * **如果**异步操作执行得**非常快**（比如数据已在缓存中），回调函数在 `start_async_read` 返回之前，就在另一个线程被执行了。
  * 那么，`cv.notify_one()` 就会在 `cv.wait()` **之前**被调用。
  * 结果就是，主线程错过了通知，将永远地等待下去。

为了解决这个问题，我们必须引入同步原语（`std::mutex`, `std::condition_variable`），这增加了代码的复杂性和开销。

-----

### 2\. 协程的解决方案：原子化的“暂停并启动”

C++ 协程通过 `co_await` 的机制设计，从根本上消除了这种竞态条件。其关键在于 `await_suspend` 的执行时机。

`co_await` 表达式的执行流程（简化版）如下：

1.  调用 `await_ready()`。如果返回 `true`，则跳过后续步骤，直接进入第 4 步。
2.  **【关键点】** 编译器生成代码，**保存当前协程的状态**。此时，协程在逻辑上**已经处于“暂停”状态**。它可以安全地被恢复了。
3.  调用 `await_suspend(handle)`。`handle` 是一个指向已暂停协程的句柄。
      * 在 `await_suspend` **内部**，我们可以安全地启动异步操作，并将 `handle` 传递给它。
      * 因为协程**已经**准备好被恢复了，所以即使异步操作立即完成并调用 `handle.resume()`，也绝对不会“丢失唤醒”。
4.  （当协程被恢复后）调用 `await_resume()` 获取结果。

这个流程确保了“进入等待状态”和“启动异步操作”这两个动作之间不存在时间间隙，它们被绑定在了一起，对于外部世界来说是原子性的。

-----

### 3\. 代码示例与并发风险分析

现在，我们用一个具体的 `Awaiter` 来演示这个机制，并暴露其中潜藏的并发风险。

```cpp
#include <iostream>
#include <coroutine>
#include <thread>
#include <chrono>
#include <atomic>
#include <string>

using namespace std::literals;

// 一个 Awaiter，它会启动一个新线程来模拟异步 I/O，并在100毫秒后恢复协程
struct AsyncOperationAwaiter {
    std::string data_to_use; // Awaiter 的成员变量
    std::atomic<int>* counter;

    AsyncOperationAwaiter(std::string data, std::atomic<int>* c) 
        : data_to_use(std::move(data)), counter(c) {}

    bool await_ready() const noexcept {
        std::cout << "    (AWAITER) await_ready: a new async op is needed.\n";
        return false; // 我们总是需要异步执行
    }

    // 这是核心部分
    void await_suspend(std::coroutine_handle<> h) {
        std::cout << "    (AWAITER) await_suspend: coroutine is now suspended.\n";

        // 将需要在新线程中使用的数据复制为局部变量
        auto local_data = data_to_use;
        
        // 启动一个新线程来执行异步任务
        std::thread([h, local_data, this] {
            std::cout << "        [Thread] Starting async work with data: " << local_data << "\n";
            std::this_thread::sleep_for(100ms); // 模拟I/O
            std::cout << "        [Thread] Async work finished. Resuming coroutine.\n";
            
            // 异步操作完成，恢复协程
            h.resume();

        }).detach();

        // ----------------- ⚠️ 危险区域 ⚠️ -----------------
        // 一旦新线程启动，并拿到了 handle，它就可能随时 `resume()` 协程。
        // `resume()` 会导致协程继续执行，并立即销毁这个 Awaiter 对象。
        // 因此，从这里开始，访问 `this` 或其成员 `data_to_use` 是极其危险的！
        
        std::cout << "    (AWAITER) await_suspend: returning, releasing control.\n";

        // 模拟一个非常快的异步完成，用以暴露问题
        // 如果上面 sleep_for 的时间很短（比如0ms），下面这行代码很可能在协程恢复后才执行
        // 此时 `this` 已经被销毁，访问 `this->counter` 将导致 use-after-free
        // this->counter->fetch_add(1); // <--- 这是一个潜在的 BUG！
        // ----------------------------------------------------
    }

    void await_resume() const noexcept {
        std::cout << "    (AWAITER) await_resume: coroutine has resumed.\n";
    }

    ~AsyncOperationAwaiter() {
        std::cout << "    (AWAITER) Destructor called.\n";
    }
};

struct Task {
    struct promise_type {
        Task get_return_object() { return {}; }
        std::suspend_never initial_suspend() { return {}; }
        std::suspend_always final_suspend() noexcept { return {}; }
        void return_void() {}
        void unhandled_exception() {}
    };
};

Task my_coroutine(std::atomic<int>* counter) {
    std::cout << "[CORO] Before co_await.\n";

    // 当 co_await 执行时，会在栈上（或协程帧上）创建一个 Awaiter 对象
    co_await AsyncOperationAwaiter("my_data", counter);
    // 当协程从这里恢复时，上面的 Awaiter 对象已经被销毁了

    std::cout << "[CORO] After co_await. Coroutine is finishing.\n";
}

int main() {
    std::atomic<int> counter = 0;
    my_coroutine(&counter);

    std::cout << "[MAIN] Coroutine returned to main thread.\n";
    std::cout << "[MAIN] Waiting for async operation to complete...\n";
    
    // 等待足够长的时间以确保协程执行完毕
    std::this_thread::sleep_for(200ms);
    std::cout << "[MAIN] Exiting.\n";
    return 0;
}
```

#### 代码执行流程与风险分析

1.  **`my_coroutine`** 开始执行，打印 `[CORO] Before co_await.`。
2.  遇到 `co_await`，一个 `AsyncOperationAwaiter` 对象被创建。
3.  **`await_ready`** 返回 `false`。
4.  **协程状态被保存**。
5.  **`await_suspend`** 被调用。它打印消息，然后**启动一个新线程**。
6.  新线程拿到了 `coroutine_handle`，开始 `sleep_for(100ms)`。
7.  与此同时，`await_suspend` 函数继续执行，打印返回消息，然后**返回**。控制权交还给 `main` 函数。
8.  **`main`** 函数继续执行，打印 `[MAIN] Coroutine returned...`。
9.  **大约 100ms 后**，新线程睡醒了，调用 `h.resume()`。
10. **协程被唤醒**，立即调用 `await_resume()`。
11. `await_resume()` 执行完毕后，`co_await` 表达式完成。`AsyncOperationAwaiter` 对象的作用域结束，其**析构函数被调用**。
12. 协程继续执行，打印 `[CORO] After co_await...`。
13. 协程执行到末尾，最终挂起在 `final_suspend`。

**并发风险点**：

想象一下，如果新线程中的 `sleep_for` 时间非常短，甚至是 0。

  * `await_suspend` 启动新线程。
  * 新线程**立即**执行 `h.resume()`。
  * 协程被恢复，`await_resume()` 被调用，**`AsyncOperationAwaiter` 对象被销毁**。
  * 与此同时，`await_suspend` 函数可能**还没来得及执行完并返回**！
  * 如果此时 `await_suspend` 中还有代码要访问 `this` 指针或其成员（比如那个被注释掉的 `this->counter->fetch_add(1)`），就会发生**悬空指针访问（Use-After-Free）**，导致未定义行为。

### 总结与黄金法则

  * **优点**：通过在 `await_suspend` 内部启动异步操作，我们完美地避免了“启动”和“等待”之间的竞态，实现了**无需锁的异步调度**。
  * **危险**：一旦你将 `coroutine_handle` 发布到另一个执行上下文（如新线程、I/O 完成端口等），你就必须假设协程可能**立即恢复**，并销毁当前的 `Awaiter` 对象。

**黄金法则**：在 `await_suspend` 方法中，一旦调用了会触发异步恢复的函数（如启动线程、提交 I/O 请求等），**后续的代码就不应再访问 `this` 指针或其任何成员**。所有需要的数据都应在此之前复制到局部变量或传递给异步操作。