### 1\. 核心匹配规则：“按类型首次匹配” (First Fit by Type)

当一个异常在 `try` 块中被 `throw` 抛出时，C++运行时系统会**按顺序**检查紧随其后的 `catch` 块：

1.  **顺序检查**：从第一个 `catch` 块开始，逐个向下检查。
2.  **类型匹配**：判断抛出的**异常对象的类型**是否与当前 `catch` 块声明要捕获的**参数类型**相匹配。
3.  **首次匹配成功即停止**：一旦找到**第一个**能够成功匹配的 `catch` 块，异常就会被该块处理。执行完这个 `catch` 块的代码后，**所有后续的 `catch` 块都将被完全忽略**。
4.  **未找到匹配**：如果在当前的 `try...catch` 结构中没有找到任何匹配的 `catch` 块，异常会继续向外层调用栈传递，直到找到一个匹配的 `catch` 块或者最终都未找到（导致程序终止）。

#### 什么是“类型匹配”？

一个 `catch (Type param)` 块能够匹配一个被 `throw` 的异常对象，如果：

  * **精确匹配**：异常对象的类型与 `Type` 完全相同。
  * **继承匹配**：异常对象的类型是 `Type` 的**公有派生类**。
  * **类型转换匹配**：存在一个明确的、无歧义的类型转换，能将异常对象类型转换为 `Type`。

-----

### 2\. `catch` 块的顺序至关重要：派生类在前，基类在后

由于“首次匹配即停止”的规则，当处理具有继承关系的异常类时，`catch` 块的顺序变得**极其重要**。

**黄金法则：永远将派生类（更具体）的 `catch` 块，放在基类（更通用）的 `catch` 块之前。**

**为什么？**
因为如果基类的 `catch` 块在前面，那么无论是抛出基类异常还是派生类异常，都会被这个基类 `catch` 块“截胡”。派生类的 `catch` 块将永远没有机会被执行，这被称为**代码不可达（Unreachable Code）**。

#### 代码示例：正确的顺序 vs. 错误的顺序

```cpp
#include <iostream>
#include <stdexcept>

// --- 错误顺序 ---
void test_wrong_order() {
    try {
        // 抛出一个更具体的 runtime_error
        throw std::runtime_error("A specific runtime error");
    }
    catch (const std::exception& e) { // 基类 std::exception 在前
        std::cerr << "Caught a generic std::exception: " << e.what() << std::endl;
    }
    catch (const std::runtime_error& e) { // 派生类 std::runtime_error 在后
        // 这一块代码永远不会被执行！
        std::cerr << "Caught a std::runtime_error: " << e.what() << std::endl;
    }
}

// --- 正确顺序 ---
void test_correct_order() {
    try {
        throw std::runtime_error("A specific runtime error");
    }
    catch (const std::runtime_error& e) { // 派生类 std::runtime_error 在前
        std::cerr << "Caught a std::runtime_error: " << e.what() << std::endl;
    }
    catch (const std::exception& e) { // 基类 std::exception 在后
        std::cerr << "Caught a generic std::exception: " << e.what() << std::endl;
    }
}
```

`test_wrong_order()` 会错误地进入第一个 `catch` 块，而 `test_correct_order()` 则会正确地进入为 `std::runtime_error` 准备的特定处理块。

-----

### 3\. 综合示例：处理多种互不相关的异常

```cpp
#include <iostream>
#include <string>
#include <stdexcept>

void process_data(int type) {
    if (type == 1) {
        throw std::runtime_error("Runtime error occurred!");
    } else if (type == 2) {
        throw std::string("A string exception."); // 抛出一个 string 对象
    } else if (type == 3) {
        throw 42; // 抛出一个 int
    } else {
        std::cout << "Processing succeeded." << std::endl;
    }
}

int main() {
    for (int i = 1; i <= 4; ++i) {
        try {
            std::cout << "Processing with type " << i << ": ";
            process_data(i);
        }
        // 捕获 std::exception 及其所有派生类
        catch (const std::exception& e) {
            std::cerr << "Caught a standard exception: " << e.what() << std::endl;
        }
        // 捕获 string 类型的异常
        catch (const std::string& s) {
            std::cerr << "Caught a string: " << s << std::endl;
        }
        // 捕获 int 类型的异常
        catch (int error_code) {
            std::cerr << "Caught an integer error code: " << error_code << std::endl;
        }
        // “安全网”：捕获所有其他类型的异常，必须放在最后
        catch (...) {
            std::cerr << "Caught an unknown exception type!" << std::endl;
        }
    }
    return 0;
}
```

**输出：**

```
Processing with type 1: Caught a standard exception: Runtime error occurred!
Processing with type 2: Caught a string: A string exception.
Processing with type 3: Caught an integer error code: 42
Processing with type 4: Processing succeeded.
```

这个例子清晰地展示了 `try` 块如何根据抛出的不同异常类型，精确地跳转到对应的 `catch` 块进行处理。

### 总结

1.  **机制**：C++ 通过**多个有序的 `catch` 块**来处理多种异常。
2.  **规则**：运行时系统会寻找**第一个类型匹配**的 `catch` 块来处理异常。
3.  **顺序**：处理有继承关系的异常时，必须将**派生类（更具体）的 `catch` 块放在基类（更通用）之前**。
4.  **安全网**：`catch(...)` 可以捕获任何类型的异常，应放在所有其他 `catch` 块的**最后**。
5.  **最佳实践**：推荐抛出从 `std::exception` 派生的自定义异常类，并\*\*按常量引用（`const T&`）\*\*进行捕获，这样可以利用多态性来组织清晰的异常处理层次结构。