这个问题涉及到协程标准和编译器生成的代码结构，我们来仔细分析一下。

---

### 1️⃣ 编译器生成的协程框架

当你写一个协程函数，例如：

```cpp
Task my_coroutine() {
    // 协程体开始
    co_await something;
    co_return;
}
```

编译器会把它转换成一个**协程状态机**，大致伪代码如下（简化版）：

```cpp
auto my_coroutine() -> Task {
    promise_type promise;

    // 1. 创建返回对象
    Task ret = promise.get_return_object();

    // 2. 初始挂起点
    co_await promise.initial_suspend(); // <-- 这一条

    try {
        // 3. 协程体真正执行
        ...协程体内容...
    } catch(...) {
        promise.unhandled_exception();
    }

    // 4. 最终挂起点
    co_await promise.final_suspend();

    return ret;
}
```

可以看到，**`initial_suspend()` 的 co\_await 是在 try/catch 之外的**。

---

### 2️⃣ 为什么设计成 try/catch 之外

* **目的**：初始挂起点是在协程体执行之前就触发的，它本身不是协程体的一部分。
* **逻辑**：如果 `initial_suspend()` 抛异常，协程体还没开始执行，显然异常不属于协程体，所以没有包在协程体的 try/catch 内。
* **影响**：异常会直接抛给调用者，而不是被协程内部的 `unhandled_exception()` 捕获。

如果把 `initial_suspend()` 放在 try/catch 里面：

* 异常会被协程内部捕获并处理，**调用者就收不到这个异常**，这可能不是期望行为。

所以标准规定：**initial\_suspend() 的异常应该直接到调用者**，协程体内的 try/catch 只处理协程体执行过程中的异常。

---

### 3️⃣ 总结

* `initial_suspend()` 在协程体之前执行，它属于“协程启动逻辑”，而不是协程体逻辑。
* 所以它在 try/catch 之外，异常直接传给调用者。
* 协程体的 try/catch 只保护 **协程体内部的代码**，不包括初始挂起点。

---

如果你愿意，我可以帮你画一张 **协程函数执行流程图**，标出 `initial_suspend()` 在 try/catch 之外、协程体在 try/catch 之内的结构，这样直观理解为什么异常传递给调用者。

你希望我画吗？
