好的，我们仔细拆解这段话，把协程中异常传播、`unhandled_exception()` 和协程帧生命周期的关系讲清楚。

---

## 1️⃣ `promise.unhandled_exception()` 的作用

当协程内部出现异常（例如 `co_return` 表达式求值失败，或者协程体里 throw）且没有被协程体内部 try/catch 捕获时：

* 异常会被转发给 `promise_type::unhandled_exception()`
* 编译器会生成调用这个方法的代码：

```cpp
try {
    // 协程体执行
} catch(...) {
    promise.unhandled_exception(); // 捕获所有异常
}
```

**作用**：

1. 捕获异常（通常用 `std::current_exception()`）
2. 存储在 promise 内部
3. 之后调用者在获取协程结果时可以重新抛出异常

---

## 2️⃣ unhandled\_exception 的实现方式

### 方式 A：存储异常

```cpp
void unhandled_exception() {
    exception = std::current_exception();  // 保存异常副本
}
```

* 不会立即破坏协程帧
* 调用者可以 later `rethrow_exception(exception)`
* 安全性高，适合普通协程使用

### 方式 B：立即重新抛出异常

```cpp
void unhandled_exception() {
    throw;  // 立即把异常抛出
}
```

* 异常直接传播到调用者或恢复者
* **协程帧会立即被销毁**
* 如果调用者假设 `resume()` 是 `noexcept`，会破坏这种抽象
* 所以这种方式只适合你完全控制谁调用 `resume()` 的场景

> Folly 的 Optional 协程就是用这种方式，直接把异常传播出去。

---

## 3️⃣ 异常传播与协程帧销毁

你的理解：

> 如果控制流通过异常传播离开协程体（通过 `co_await promise.initial_suspend()`、`promise.unhandled_exception()` 或 `co_await promise.final_suspend()`，或协程同步完成），则协程帧会在返回给调用者/恢复者前自动销毁。

拆解：

* **协程帧**是存储局部变量、挂起点、promise 的内存块
* 协程中任何异常传播出去，都会触发 **栈展开（stack unwinding）**
* 在栈展开过程中：局部变量析构、协程帧析构
* 也就是说，异常传播 **会销毁协程帧**，保证资源不会泄漏

⚠️ 但这里有问题：如果 `resume()` 被假设为 `noexcept`，直接抛异常会破坏这一假设 → 稳定性风险

---

## 4️⃣ 为什么规范建议不要在 initial/final/unhandled\_exception 抛异常

* `initial_suspend()`：挂起点前执行，如果抛异常 → 调用者直接收到异常 → 协程帧可能已 partially 初始化
* `final_suspend()`：协程结束挂起点，如果抛异常 → 协程帧已部分析构，可能造成重复释放
* `unhandled_exception()`：如果立即抛出异常 → 同步销毁协程帧，可能破坏 `resume() noexcept` 假设

**结论**：目前的最佳实践是 **这些地方都不抛异常**，而是保存异常，让调用者 later 处理。

---

## 5️⃣ 总结

1. **unhandled\_exception()** 捕获协程体未处理的异常
2. 可以选择：

   * **存储异常** → 安全、延迟抛出
   * **立即抛异常** → 协程帧立即销毁，但风险较高
3. **异常传播会触发栈展开** → 协程帧和局部变量析构
4. **不要在 initial\_suspend、final\_suspend、unhandled\_exception 抛异常**
5. 未来 Coroutines TS 可能会明确规定这些行为

---

如果你愿意，我可以画一张**协程异常传播 → unhandled\_exception → 协程帧销毁 → 调用者重新抛出**的流程图，把整个异常路径和协程帧生命周期标清楚。

你希望我画吗？
