### 1\. 构造函数可以（且应该）抛出异常

**可以吗？**：**可以**。
**为什么？**：构造函数的唯一使命是成功地初始化一个对象，使其进入一个可用状态。它**没有返回值**，因此无法像普通函数一样通过返回错误码来报告失败。

所以，当一个对象因为某些原因（如无法分配内存、无法打开所需文件、传入的参数无效等）**无法被成功构造**时，**抛出异常是唯一、也是最清晰的**通知调用方“创建失败”的方法。

#### 面临的问题：资源泄漏

正如您所精准指出的，C++语言有一个核心规则：**只有完全构造成功的对象，才会被析构。**
一个对象的构造过程，只有在其构造函数**执行完毕**时才算完成。

  * **如果构造函数中途抛出异常**：
    1.  该对象的构造过程被视为失败。
    2.  该对象的**析构函数将永远不会被调用**。
    3.  在这个异常抛出**之前**，如果构造函数已经通过 `new` 等方式手动申请了任何资源，而又没有相应的 `delete`，那么这些资源就会**永久泄漏**。

**代码示例（有泄漏风险）**：

```cpp
class Risky {
private:
    int* m_ptr1;
    int* m_ptr2;
public:
    Risky() {
        m_ptr1 = new int(10); // 1. 资源1成功获取
        
        // 假设这里发生了一个错误，例如内存不足
        throw std::bad_alloc();
        
        m_ptr2 = new int(20); // 2. 这行代码永远不会执行
    }

    ~Risky() {
        delete m_ptr1;
        delete m_ptr2;
    }
};

void test() {
    try {
        Risky r;
    }
    catch (const std::exception& e) {
        // 在这里捕获了异常，但 ~Risky() 从未被调用
        // m_ptr1 指向的内存已经泄漏了！
    }
}
```

#### 解决方案：RAII (资源获取即初始化)

您提到的 `auto_ptr` 正是这个思想的早期体现。在现代C++中，我们使用更安全、更强大的**智能指针**。

**核心思想**：**不要在构造函数中管理裸指针**。应该将所有资源都封装在遵循RAII原则的对象中（如智能指针、`std::vector`、`std::fstream`等）。

**工作原理**：
C++保证，即使构造函数中途抛出异常，所有**已经完全构造好的成员变量**，它们的**析构函数会被正确地、逆序地调用**。

**代码示例（异常安全）**：

```cpp
#include <memory>

class Safe {
private:
    // 使用智能指针管理资源
    std::unique_ptr<int> m_ptr1;
    std::unique_ptr<int> m_ptr2;
public:
    Safe() 
        : m_ptr1(std::make_unique<int>(10)) // 1. m_ptr1 构造成功并获取资源
    {
        // 假设这里发生了一个错误
        throw std::runtime_error("Something failed!");

        m_ptr2 = std::make_unique<int>(20); // 2. 不会执行
    }
    
    // 析构函数现在可以是默认的，智能指针会自动处理
    ~Safe() = default; 
};

void test_safe() {
    try {
        Safe s;
    }
    catch (const std::exception& e) {
        // 异常被捕获。
        // 虽然 ~Safe() 不会被调用，但成员 m_ptr1 的析构函数会被自动调用，
        // 从而释放它所管理的内存。没有发生内存泄漏！
    }
}
```

**结论**：构造函数可以而且应该在失败时抛出异常。为了防止资源泄漏，必须使用 **RAII** 技术来管理所有资源。

-----

### 2\. 析构函数绝对不应该抛出异常

**可以吗？**：语法上**可以**，但实践中是**绝对禁止**的。让异常从析构函数中“逃逸”出来，是一种极其危险的行为。

#### 为什么？—— 导致程序立即终止

正如您在第3点和第4点中指出的，这会导致严重问题。
**核心原因**：析构函数常常是在**栈回溯（Stack Unwinding）的过程中，为另一个已经存在的异常**进行“善后清理”时被调用的。

**灾难场景（双重异常）**：

1.  程序中的某个函数 `func()` 抛出了一个异常 `E1`。
2.  C++运行时系统开始进行栈回溯，销毁 `func()` 作用域内的所有局部对象。
3.  在销毁其中一个对象 `obj` 时，调用了它的析构函数 `~obj()`。
4.  不幸的是，`~obj()` 的内部也执行了一个可能失败的操作，并抛出了一个新的异常 `E2`。
5.  此时，系统中同时存在两个**未被处理的异常** (`E1` 和 `E2`)。C++语言标准规定，它**无法处理**这种情况。
6.  **最终后果**：程序会立即调用 `std::terminate()`，通常导致程序**异常终止**，不会有任何进一步的清理或错误处理。

#### 解决方案：在析构函数内部“消化”所有异常

如果析构函数中包含必须执行但可能失败的操作（例如关闭一个可能断开的网络连接），**必须**将这个操作包裹在 `try...catch` 块中，并**在析构函数内部处理掉所有异常**。

```cpp
class MyConnection {
public:
    // C++11及以后，析构函数默认是 noexcept(true) 的
    ~MyConnection() noexcept {
        try {
            // 这个操作可能会抛出异常
            close_connection(); 
        }
        catch (...) {
            // 捕获所有异常
            // 可以在这里记录日志，但绝不能让异常逃逸出去！
            // Swallow the exception.
        }
    }
};
```

**结论**：析构函数必须是可靠的、不会失败的。应将它们声明为 `noexcept`，并确保没有任何异常能从其中传播出来。