# async用法

```cpp
std::string fetchDataFromDB(std::string query){
  std::this_thread::sleep_for(std::chrono::seconds(2));
  std::cout << "children thread has finish misson" << std::endl;
  return std::string("Data:" + query);
}

void use_async()
{
  std::future<std::string> result = std::async(std::launch::async,fetchDataFromDB,"Data");
  std::cout << "Main thread do somthing...." << std::endl;
  std::string value = result.get();
  std::cout << value << std::endl;
}

void use_defered_async()
{
  std::future<std::string> result = std::async(std::launch::deferred,fetchDataFromDB,"Data");
  std::this_thread::sleep_for(std::chrono::seconds(3));
  std::cout << "Main Thread do somthing..." << std::endl;
  std::string value = result.get();
  std::cout << value << std::endl;
}
```

通过使用`std::async`可以创建一个异步任务，该函数会返回一个`std::future<T>`对象，用于接收结果。

`std::async`的第一个参数有两中选择:
1. `std::launch::async`: 表示该异步任务立马执行。
2. `std::launch::defered`: 表示该异步任务只有再调用`future.get()`或`future.wait()`成员方法时，才会执行。

>如果不指定第一个参数，会采用默认选项(`std::launch::async | std::launch::defered`)，函数的具体行为取决于编译器。


# future的wait()和get()

1. **std::future::get()**
	`std::future::get()`是一个阻塞调用，用于获取`std::future`对象表示的值或者异常。如果异步任务还没有完成，`get()`会阻塞当前进程，直到任务完成。如果任务已完成，`get()`会立即返回任务的结果。重要的是，`get()`只能调用一次，因为他会移动或消耗掉`std::future`对象的状态。一旦`get()`被调用，`std::future`对象就不能在被调用用来获取结果。
2. **std::future::wait()**
	`std::future::wait()` 也是一个阻塞调用，但它与 `get()` 的主要区别在于 `wait()` 不会返回任务的结果。它只是等待异步任务完成。如果任务已经完成，`wait()` 会立即返回。如果任务还没有完成，`wait()` 会阻塞当前线程，直到任务完成。与 `get()` 不同，`wait()` 可以被多次调用，它不会消耗掉 `std::future` 对象的状态。
	


`std::future`的`wait_for()`或`wait_until()`方法来检查异步操作是否完成。这些方法返回一个表示操作状态的`std::future_status`值。

```cpp
void use_wait_for()
{
  std::future<std::string> result = std::async(std::launch::async,fetchDataFromDB,"Data");
  if(result.wait_for(std::chrono::seconds(1)) == std::future_status::ready){
    std::cout << "Task finished quickly! Result = " << result.get() << std::endl;
  }else{
    std::cout << "Still waiting... doing other work\n";
    result.wait();
    std::cout << "Done.Result = " << result.get() << std::endl; //错误！get()二次调用会抛出异常
  }

}
```

**future_status枚举值**

```cpp
enum class future_status{
	ready, //异步任务已完成
	timeout, //等待时间超时，任务未完成
	defered //任务是"延迟执行“的(即launch::defered)
}
```

所以在实际使用中，建议加判断：

```cpp
if (fut.wait_for(std::chrono::seconds(0)) == std::future_status::ready) {
    int value = fut.get();
    ...
}

```

# 将任务和future关联

`std::packaged_task`和`std::future`是C++11中引入的两个类，它们用于处理异步任务的结果。
`std::packaged_task`是一个可调用目标，它包装了一个任务，该任务可以在另一个线程上运行。它可以捕获任务返回值或异常，并将其存储在`std::future`对象中，以便以后使用。
`std::future`代表一个异步操作的结果。它可以用于从异步任务中获取返回值或异常。
以下是使用`std::packaged_task`和`std::future`的基本步骤:

1. 创建一个std::packaged_task对象，该对象包装了要执行的任务。
2. 调用std::packaged_task对象的get_future()方法，该方法返回一个与任务关联的std::future对象。
3. 在另一个线程上调用std::packaged_task对象的operator()，以执行任务。
4. 在需要任务结果的地方，调用与任务关联的std::future对象的get()方法，以获取任务的返回值或异常。

```cpp
int my_task() {
    std::this_thread::sleep_for(std::chrono::seconds(5));
    std::cout << "my task run 5 s" << std::endl;
    return 42;
}

void use_package() {
    // 创建一个包装了任务的 std::packaged_task 对象  
    std::packaged_task<int()> task(my_task);

    // 获取与任务关联的 std::future 对象  
    std::future<int> result = task.get_future();

    // 在另一个线程上执行任务  
    std::thread t(std::move(task));
    t.detach(); // 将线程与主线程分离，以便主线程可以等待任务完成  

    // 等待任务完成并获取结果  
    int value = result.get();
    std::cout << "The result is: " << value << std::endl;

}
```

在上面的示例中，我们创建了一个包装了任务的std::packaged_task对象，并获取了与任务关联的std::future对象。然后，我们在另一个线程上执行任务，并等待任务完成并获取结果。最后，我们输出结果。

我们可以使用 std::function 和 std::package_task 来包装带参数的函数。std::package_task 是一个模板类，它包装了一个可调用对象，并允许我们将其作为异步任务传递。

**注意点:**

> **`std::packaged_task` 对象只能被调用一次**，也就是说：
>
> * 你只能调用它一次（比如通过 `task()` 或传给线程），
> * 第二次再调用它会 **抛异常或导致未定义行为**，因为它的 `future` 只能设置一次结果。

```cpp
#include <iostream>
#include <future>

int add(int a, int b) {
    return a + b;
}

int main() {
    std::packaged_task<int(int, int)> task(add);
    std::future<int> fut = task.get_future();

    task(2, 3);  // ✅ 第一次调用 OK，fut 中有值了

    // 再次调用会出错（因为 future 的值只能设置一次）
    // task(4, 5);  // ❌ 错误！future 只能被设置一次

    std::cout << "Result: " << fut.get() << std::endl;

    return 0;
}
```

如果你尝试再次调用 `task(4, 5)`，会发生以下几种情况之一（具体行为与实现相关）：

* 抛出异常：`std::future_error`（原因：`promise_already_satisfied`）
* 程序崩溃（未定义行为）
* 根本不运行第二次逻辑


## 为什么只能调用一次？

这是由 **`std::future` 的设计限制**决定的：

* 每个 `future` 只能获取一次结果（`get()`）
* 每个 `promise`（或 packaged\_task 内部的 promise）也只能 **设置一次值**

当你第一次调用 `task()` 时，它已经设置了值，`future` 就绑定上了结果。
后面再调用就**无法再次存入值**，因此标准库不允许这样做。


## 如果想重复用怎么办？

就**重新创建一个 `packaged_task` 对象**：

```cpp
std::packaged_task<int(int, int)> task(add);
auto fut1 = task.get_future();
task(1, 2);
std::cout << fut1.get() << std::endl;

// 重新构造一个新的任务
std::packaged_task<int(int, int)> task2(add);
auto fut2 = task2.get_future();
task2(3, 4);
std::cout << fut2.get() << std::endl;
```


# promise用法

C++11引入了`std::promise`和`std::future`两个类，用于实现异步编程。`std::promise`用于在某一线程中设置某个值或异常，而`std::future`则用于在另一个线程中获取这个值或异常。

下面是`std::promise`的基本用法:

```cpp
void set_value(std::promise<int> prom){
  //设置promise的值
  prom.set_value(10);
}

void use_promise(){
  //创建一个promise对象
  std::promise<int> prom;
  //获取与promise相关联的future对象
  std::future<int> fut = prom.get_future();
  //在新线程中设置promise的值
  std::thread t(set_value,std::move(prom));
  // 在主线程中获取future的值
  std::cout << "Waiting for the thread to set the value...\n";
  std::cout << "Value set by the thread: " << fut.get() << '\n';
  t.join();
}
```

在上面的代码中，我们首先创建了一个`std::promise<int>`对象，然后通过调用`get_future()`方法获取与之相关联的`std::future<int>`对象。然后，我们在新线程中通过调用`set_value()`方法设置`promise`的值，并在主线程中通过调用`fut.get()`方法获取这个值。注意，在调用`fut.get()`方法时，如果promise的值还没有被设置，则该方法会阻塞当前线程，直到值被设置为止。

除了`set_value()`方法外，`std::promise`还有一个`set_exception()`方法，用于设置异常。该方法接收一个`std::exception_ptr`参数，该参数可以通过调用`std::current_execption()`方法获取。

```cpp
void set_execption(std::promise<void> prom){
  try{
    std::runtime_error("An error occur int childthread ....");
  }catch(...){
    prom.set_exception(std::current_exception());
  }
}

void use_execption(){
  std::promise<void> prom;
  std::future<void> fut = prom.get_future();
  std::thread t(set_execption,std::move(prom));
  try{
    std::cout << "Waiting for the thread to set the execption...\n";
  } catch(const std::exception& e)
  {
    std::cout << "Exception set by the thread: " << e.what() << '\n';
  }
  t.join();
}
```

**当我们使用promise时要注意一点，如果promise被释放了，而其他线程还未使用与promise关联的future，当其使用这个future会报错。如下是一段错误展示：

```cpp
void use_promise_destruct(){
  std::thread t;
  std::future<int> fut;
  {
    //创建一个promise对象
    std::promise<int> prom;
    //获取与promise相关联的future对象
    std::future<int> fut = prom.get_future();
    //在新线程中设置promise的值
    t = std::thread(set_value,std::move(prom));
  }
  //在主线程中获取future的值
  std::cout << "Waiting for the thread to set the value...\n";
  std::cout << "Value set by the thread:" << fut.get() << '\n';
  t.join();
}
```

**随着局部作用域}的结束，prom可能被释放也可能会被延迟释放，如果立即释放则fut.get()获取的值会报error_value的错误。**

# 总结

## 🔁 回顾：`std::promise` 的作用

* `std::promise<T>` 是用来**在线程间传递某个结果或异常**的。
* 和它绑定的 `std::future<T>` 可以在**另一个线程中获取这个结果/异常**。
* 通常在**异步编程**或**线程通信中**使用。


## ❗问题核心：为什么 `std::promise` 被销毁后，`future.get()` 会抛异常？

这是因为：

## ✅ promise 的规则

* 你必须 **显示地调用 `promise.set_value()` 或 `set_exception()`** 来满足 `future` 的需求。
* 如果 `promise` 被销毁时，还**没有调用过这两个函数**，那 `future.get()` 调用时会抛出一个异常。

### ❌ 报错机制

* 当 `std::promise` 被销毁而没有设置值或异常时，`std::future` 内部状态变成“broken promise（承诺断裂）”。
* 此时，调用 `fut.get()` 会抛出：

```cpp
std::future_error: Broken promise
```

---

## 📌 举个更清晰的例子

```cpp
std::future<int> fut;
{
    std::promise<int> prom;
    fut = prom.get_future();
    // 注意：这里没有 prom.set_value(x) 也没有 prom.set_exception(...)
}
// prom 在这里被析构，future 变成 "broken promise"

int val = fut.get();  // ❗会抛出 std::future_error
```

---

## 🧠 原因图解

```
  Thread A (主线程)                    Thread B (异步任务线程)

  promise<int> prom;                  [不存在 or 还没执行任务]
      |
      +--> future<int> fut;

  // prom 被销毁了
  // 没有调用 set_value or set_exception

  fut.get();     --> ❗ std::future_error("Broken promise")
```

---

## ✅ 如何避免这类问题？

### 方法 1：确保 promise 设置了值或异常

```cpp
prom.set_value(42);
// 或者在异常分支中 set_exception()
```

### 方法 2：使用 `std::shared_ptr<std::promise<T>>`

* 用于多个线程可能同时持有或延迟释放 promise 的情况。

```cpp
auto prom = std::make_shared<std::promise<int>>();
std::future<int> fut = prom->get_future();

std::thread([prom]() {
    prom->set_value(123);  // shared_ptr 保证它不会过早销毁
}).detach();

int result = fut.get();  // 安全
```


## 🔄 与 `set_exception()` 的配合

* 在 catch(...) 中调用 `set_exception(std::current_exception())` 是标准做法。
* 可以让 `fut.get()` 直接 `throw` 出原来的异常。


# 共享类型的future
当我们需要多个线程等待同一个执行结果时，需要使用std::shared_future。

以下是一个适合使用std::shared_future的场景，多个线程等待同一个异步操作的结果：
假设你有一个异步任务，需要多个线程等待其完成，然后这些线程需要访问任务的结果。在这种情况下，你可以使用std::shared_future来共享异步任务的结果。

```cpp
void myFunction(std::promise<int>&& promise){
  //模拟一些工作
  std::this_thread::sleep_for(std::chrono::seconds(1));
  promise.set_value(42);
}

void threadFunction(std::shared_future<int> future){
  try{
    int result = future.get();
    std::cout << "Result:" << result << std::endl;
  }
  catch(const std::future_error& e){
    std::cout << "Future error: " << e.what() << std::endl;
  }
}

void use_shared_future(){
  std::promise<int> promise;
  std::shared_future<int> future = promise.get_future();

  std::thread myThread1(myFunction,std::move(promise)); //将promise移动到线程中

  //使用shared（）方法获取新的 shared_future对象
  std::thread myThread2(threadFunction,future);
  std::thread myThread3(threadFunction,future);

  myThread1.join();
  myThread2.join();
  myThread3.join();
}
```

在这个示例中，我们创建了一个`std::promise<int>`对象`promise`和一个与之关联的`std::shared_future<int>`对象`future`。然后，我们将`promise`对象移动到另一个线程`myThread1`中，该线程将执行myFunction函数，并在完成后设置`promise`的值。我们还创建了两个线程`myThread2和myThread3`，它们将等待`future`对象的结果。如果`myThread1`成功地设置了`promise`的值，那么`future.get()`将返回该值。这些线程可以同时访问和等待`future`对象的结果，而不会相互干扰。

但是大家要注意，如果一个future被移动给两个shared_future是错误的。

```cpp
void use_shared_future() {
    std::promise<int> promise;
    std::shared_future<int> future = promise.get_future();

    std::thread myThread1(myFunction, std::move(promise)); // 将 promise 移动到线程中

    std::thread myThread2(threadFunction, std::move(future));
    std::thread myThread3(threadFunction, std::move(future));

    myThread1.join();
    myThread2.join();
    myThread3.join();
}
```

这种用法是错误的，一个`future`通过隐式构造传递给`shared_future`之后，这个`shared_future`被移动传递给两个线程是不合理的，因为第一次移动后`shared_future`的生命周期被转移了，接下来`myThread3`构造时用的`std::move(future)`future已经失效了，会报错，一般都是`no state `之类的错误。

但当 多个线程都需要等待同一个任务结果时，就要用 `std::shared_future<T>`，它
- 可以**被复制**；
- 每个副本都可以调用 .get()；
- .get() **不会消耗状态**（不像 std::future）；
- 所有线程在任务完成后都可以拿到结果。

# 异常处理
`std::future`是C++的一个模板类，它用于表示一个可能还没有准备好的异步操作结果。你可以通过调用`std::future::get`方法来获取这个结果。如果在获取结果时发送了异常，呢么`std::future::get`会重新抛出这个异常。

```cpp
void may_throw(){
  throw std::runtime_error("Oops,something went wrong!");
}

void use_catch(){
  std::future<void> result(std::async(std::launch::async,may_throw));
  try{
    result.get();
  }catch(const std::exception& e){
    std::cout << e.what() << std::endl;
  }
}
```
